# Generated by Django 4.2 on 2024-10-02 07:29

from django.db import migrations, models


class Migration(migrations.Migration):

    dependencies = [
        ('core', '0037_alter_receipt_options'),
    ]

    operations = [
        migrations.CreateModel(
            name='AppError',
            fields=[
                ('id', models.BigAutoField(auto_created=True, primary_key=True, serialize=False, verbose_name='ID')),
                ('source', models.CharField(choices=[('1', 'Основной бот'), ('2', 'Бот для водителей'), ('3', 'Бот для Самарканда'), ('4', 'Бот с отчетами'), ('5', 'Админка')], max_length=30, verbose_name='Источник ошибки')),
                ('error_type', models.CharField(choices=[('1', 'Ошибка редактирования/удаления сообщения'), ('2', 'Ошибка отправки сообщения'), ('3', 'Ошибка отправки точки в circuit'), ('4', 'Ошибка создания пользователя в iCount'), ('5', 'Ошибка создания квитанции в iCount'), ('6', 'Ошибка передачи данных в google table')], max_length=30, verbose_name='Тип ошибки')),
                ('main_user', models.CharField(blank=True, max_length=50, null=True, verbose_name='Пользователь, у которого произошла ошибка')),
                ('connected_user', models.CharField(blank=True, max_length=50, null=True, verbose_name='Связанный с ошибкой пользователь')),
                ('description', models.TextField(blank=True, null=True, verbose_name='Описание ошибки')),
                ('created_at', models.DateTimeField(auto_now_add=True, verbose_name='Дата создания')),
                ('resolved', models.BooleanField(blank=True, default=None, null=True, verbose_name='Проблема решена?')),
            ],
            options={
                'verbose_name': 'ошибка',
                'verbose_name_plural': 'ошибки',
                'ordering': ('-created_at',),
            },
        ),
    ]
